<?xml version="1.0" ?>
<!-- =================================================================================== -->
<!-- |    This document was autogenerated by xacro from cute_300es.urdf.xacro          | -->
<!-- |    EDITING THIS FILE BY HAND IS NOT RECOMMENDED                                 | -->
<!-- =================================================================================== -->
<robot name="cute_300es" xmlns:xacro="http://www.ros.org/wiki/xacro">
  <material name="black">
    <color rgba="0.0 0.0 0.0 1.0"/>
  </material>
  <material name="blue">
    <color rgba="0.0 0.0 0.8 1.0"/>
  </material>
  <material name="green">
    <color rgba="0.0 0.8 0.0 1.0"/>
  </material>
  <material name="grey">
    <color rgba="0.2 0.2 0.2 1.0"/>
  </material>
  <material name="orange">
    <color rgba="1.0 0.423529411765 0.0392156862745 1.0"/>
  </material>
  <material name="brown">
    <color rgba="0.870588235294 0.811764705882 0.764705882353 1.0"/>
  </material>
  <material name="red">
    <color rgba="0.8 0.0 0.0 1.0"/>
  </material>
  <material name="white">
    <color rgba="1.0 1.0 1.0 1.0"/>
  </material>
  <material name="yellow">
    <color rgba="0.792156862745 0.819607843137 0.0 1.0"/>
  </material>
  <material name="gray">
    <color rgba="0.752941176471 0.752941176471 0.752941176471 1.0"/>
  </material>
  <!-- ros_control plugin -->
  <gazebo>
    <plugin filename="libgazebo_ros_control.so" name="gazebo_ros_control">
      <legacyModeNS>true</legacyModeNS>
    </plugin>
  </gazebo>
  <gazebo reference="cute_base_link">
    <visual name="visual">
      <material>
        <script>
          <uri>file://media/materials/scripts/gazebo.material</uri>
          <name>Gazebo/Grey</name>
        </script>
      </material>
    </visual>
  </gazebo>
  <gazebo reference="part1">
    <visual name="visual">
      <material>
        <script>
          <uri>file://media/materials/scripts/gazebo.material</uri>
          <name>Gazebo/Yellow</name>
        </script>
      </material>
    </visual>
  </gazebo>
  <gazebo reference="part2">
    <visual name="visual">
      <material>
        <script>
          <uri>file://media/materials/scripts/gazebo.material</uri>
          <name>Gazebo/Grey</name>
        </script>
      </material>
    </visual>
  </gazebo>
  <gazebo reference="part3">
    <visual name="visual">
      <material>
        <script>
          <uri>file://media/materials/scripts/gazebo.material</uri>
          <name>Gazebo/Yellow</name>
        </script>
      </material>
    </visual>
  </gazebo>
  <gazebo reference="part4">
    <visual name="visual">
      <material>
        <script>
          <uri>file://media/materials/scripts/gazebo.material</uri>
          <name>Gazebo/Grey</name>
        </script>
      </material>
    </visual>
  </gazebo>
  <gazebo reference="part5">
    <visual name="visual">
      <material>
        <script>
          <uri>file://media/materials/scripts/gazebo.material</uri>
          <name>Gazebo/Yellow</name>
        </script>
      </material>
    </visual>
  </gazebo>
  <gazebo reference="part6">
    <visual name="visual">
      <material>
        <script>
          <uri>file://media/materials/scripts/gazebo.material</uri>
          <name>Gazebo/Grey</name>
        </script>
      </material>
    </visual>
  </gazebo>
  <gazebo reference="part7">
    <visual name="visual">
      <material>
        <script>
          <uri>file://media/materials/scripts/gazebo.material</uri>
          <name>Gazebo/Grey</name>
        </script>
      </material>
    </visual>
  </gazebo>
  <gazebo reference="claw1">
    <visual name="visual">
      <material>
        <script>
          <uri>file://media/materials/scripts/gazebo.material</uri>
          <name>Gazebo/Grey</name>
        </script>
      </material>
    </visual>
  </gazebo>
  <gazebo reference="claw2">
    <visual name="visual">
      <material>
        <script>
          <uri>file://media/materials/scripts/gazebo.material</uri>
          <name>Gazebo/Grey</name>
        </script>
      </material>
    </visual>
  </gazebo>
  <transmission name="joint1_trans">
    <type>transmission_interface/SimpleTransmission</type>
    <joint name="joint1">
      <hardwareInterface>hardware_interface/PositionJointInterface</hardwareInterface>
    </joint>
    <actuator name="joint1_motor">
      <mechanicalReduction>1</mechanicalReduction>
    </actuator>
  </transmission>
  <transmission name="joint2_trans">
    <type>transmission_interface/SimpleTransmission</type>
    <joint name="joint2">
      <hardwareInterface>hardware_interface/PositionJointInterface</hardwareInterface>
    </joint>
    <actuator name="joint2_motor">
      <mechanicalReduction>1</mechanicalReduction>
    </actuator>
  </transmission>
  <transmission name="joint3_trans">
    <type>transmission_interface/SimpleTransmission</type>
    <joint name="joint3">
      <hardwareInterface>hardware_interface/PositionJointInterface</hardwareInterface>
    </joint>
    <actuator name="joint3_motor">
      <mechanicalReduction>1</mechanicalReduction>
    </actuator>
  </transmission>
  <transmission name="joint4_trans">
    <type>transmission_interface/SimpleTransmission</type>
    <joint name="joint4">
      <hardwareInterface>hardware_interface/PositionJointInterface</hardwareInterface>
    </joint>
    <actuator name="joint4_motor">
      <mechanicalReduction>1</mechanicalReduction>
    </actuator>
  </transmission>
  <transmission name="joint5_trans">
    <type>transmission_interface/SimpleTransmission</type>
    <joint name="joint5">
      <hardwareInterface>hardware_interface/PositionJointInterface</hardwareInterface>
    </joint>
    <actuator name="joint5_motor">
      <mechanicalReduction>1</mechanicalReduction>
    </actuator>
  </transmission>
  <transmission name="joint6_trans">
    <type>transmission_interface/SimpleTransmission</type>
    <joint name="joint6">
      <hardwareInterface>hardware_interface/PositionJointInterface</hardwareInterface>
    </joint>
    <actuator name="joint6_motor">
      <mechanicalReduction>1</mechanicalReduction>
    </actuator>
  </transmission>
  <transmission name="joint7_trans">
    <type>transmission_interface/SimpleTransmission</type>
    <joint name="joint7">
      <hardwareInterface>hardware_interface/PositionJointInterface</hardwareInterface>
    </joint>
    <actuator name="joint7_motor">
      <mechanicalReduction>1</mechanicalReduction>
    </actuator>
  </transmission>
  <transmission name="claw_trans_1">
    <type>transmission_interface/SimpleTransmission</type>
    <joint name="claw">
      <hardwareInterface>hardware_interface/EffortJointInterface</hardwareInterface>
    </joint>
    <actuator name="claw_motor_1">
      <mechanicalReduction>1</mechanicalReduction>
    </actuator>
  </transmission>
  <transmission name="claw_trans_2">
    <type>transmission_interface/SimpleTransmission</type>
    <joint name="claw_pris2">
      <hardwareInterface>hardware_interface/EffortJointInterface</hardwareInterface>
    </joint>
    <actuator name="claw_motor_2">
      <mechanicalReduction>1</mechanicalReduction>
    </actuator>
  </transmission>
  <link name="world"/>
  <joint name="world_base" type="fixed">
    <origin rpy="0 0 1.57079632679" xyz="0 0 0"/>
    <parent link="world"/>
    <child link="cute_base_link"/>
  </joint>
  <link name="cute_base_link">
    <inertial>
      <origin rpy="0 0 0" xyz="-0.00099787 0.019958 0.22081"/>
      <mass value="9.0546"/>
      <inertia ixx="0.23138" ixy="0.00045611" ixz="-0.0096898" iyy="0.23735" iyz="-0.0083689" izz="0.059867"/>
    </inertial>
    <visual>
      <origin rpy="0 0 0" xyz="0 0 0"/>
      <geometry>
        <mesh filename="package://cute_model/meshes/cute_300es/base_link.STL"/>
      </geometry>
      <material name="gray"/>
    </visual>
    <collision>
      <origin rpy="0 0 0" xyz="0 0 0"/>
      <geometry>
        <mesh filename="package://cute_model/meshes/cute_300es/base_link.STL"/>
      </geometry>
    </collision>
  </link>
  <link name="part1">
    <inertial>
      <origin rpy="0 0 0" xyz="0.0011123 -0.017941 0.13361"/>
      <mass value="9.0546"/>
      <inertia ixx="0.23138" ixy="0.00045611" ixz="0.0096898" iyy="0.23735" iyz="0.0083689" izz="0.059867"/>
    </inertial>
    <visual>
      <origin rpy="0 0 0" xyz="0 0 0"/>
      <geometry>
        <mesh filename="package://cute_model/meshes/cute_300es/part1.STL"/>
      </geometry>
      <material name="yellow"/>
    </visual>
    <collision>
      <origin rpy="0 0 0" xyz="0 0 0"/>
      <geometry>
        <mesh filename="package://cute_model/meshes/cute_300es/part1.STL"/>
      </geometry>
    </collision>
  </link>
  <joint name="joint1" type="revolute">
    <origin rpy="0 0 3.14159265359" xyz="0.00011439 0.0020169 0.0872"/>
    <parent link="cute_base_link"/>
    <child link="part1"/>
    <axis xyz="0 0 1"/>
    <limit effort="120" lower="-2.5" upper="2.5" velocity="4.0"/>
  </joint>
  <link name="part2">
    <inertial>
      <origin rpy="0 0 0" xyz="-0.00099787 0.018042 0.070815"/>
      <mass value="9.0546"/>
      <inertia ixx="0.23138" ixy="0.00045611" ixz="-0.0096898" iyy="0.23735" iyz="-0.0083689" izz="0.059867"/>
    </inertial>
    <visual>
      <origin rpy="0 0 0" xyz="0 0 0"/>
      <geometry>
        <mesh filename="package://cute_model/meshes/cute_300es/part2.STL"/>
      </geometry>
      <material name="gray"/>
    </visual>
    <collision>
      <origin rpy="0 0 0" xyz="0 0 0"/>
      <geometry>
        <mesh filename="package://cute_model/meshes/cute_300es/part2.STL"/>
      </geometry>
    </collision>
  </link>
  <joint name="joint2" type="revolute">
    <origin rpy="0 0 -3.14159265359" xyz="0.00011439 0.0001016 0.0628"/>
    <parent link="part1"/>
    <child link="part2"/>
    <axis xyz="0 1 0"/>
    <limit effort="120" lower="-1.8" upper="1.8" velocity="4.0"/>
  </joint>
  <link name="part3">
    <inertial>
      <origin rpy="0 0 0" xyz="-0.00099787 0.018033 -0.0060119"/>
      <mass value="9.0546"/>
      <inertia ixx="0.23138" ixy="0.00045611" ixz="-0.0096898" iyy="0.23735" iyz="-0.0083689" izz="0.059867"/>
    </inertial>
    <visual>
      <origin rpy="0 0 0" xyz="0 0 0"/>
      <geometry>
        <mesh filename="package://cute_model/meshes/cute_300es/part3.STL"/>
      </geometry>
      <material name="yellow"/>
    </visual>
    <collision>
      <origin rpy="0 0 0" xyz="0 0 0"/>
      <geometry>
        <mesh filename="package://cute_model/meshes/cute_300es/part3.STL"/>
      </geometry>
    </collision>
  </link>
  <joint name="joint3" type="revolute">
    <origin rpy="0 0 0" xyz="0 0 0.076827"/>
    <parent link="part2"/>
    <child link="part3"/>
    <axis xyz="0 0 1"/>
    <limit effort="120" lower="-2.5" upper="2.5" velocity="4.0"/>
  </joint>
  <link name="part4">
    <inertial>
      <origin rpy="0 0 0" xyz="-0.00099787 0.016583 -0.054842"/>
      <mass value="9.0546"/>
      <inertia ixx="0.23138" ixy="0.00045611" ixz="-0.0096898" iyy="0.23735" iyz="-0.0083689" izz="0.059867"/>
    </inertial>
    <visual>
      <origin rpy="0 0 0" xyz="0 0 0"/>
      <geometry>
        <mesh filename="package://cute_model/meshes/cute_300es/part4.STL"/>
      </geometry>
      <material name="gray"/>
    </visual>
    <collision>
      <origin rpy="0 0 0" xyz="0 0 0"/>
      <geometry>
        <mesh filename="package://cute_model/meshes/cute_300es/part4.STL"/>
      </geometry>
    </collision>
  </link>
  <joint name="joint4" type="revolute">
    <origin rpy="0 0 0" xyz="0 0.00145 0.04883"/>
    <parent link="part3"/>
    <child link="part4"/>
    <axis xyz="0 1 0"/>
    <limit effort="120" lower="-1.8" upper="1.8" velocity="4.0"/>
  </joint>
  <link name="part5">
    <inertial>
      <origin rpy="0 0 0" xyz="0.016583 0.0024479 -0.12147"/>
      <mass value="9.0546"/>
      <inertia ixx="0.23735" ixy="-0.00045611" ixz="-0.0083689" iyy="0.23138" iyz="0.0096898" izz="0.059867"/>
    </inertial>
    <visual>
      <origin rpy="0 0 0" xyz="0 0 0"/>
      <geometry>
        <mesh filename="package://cute_model/meshes/cute_300es/part5.STL"/>
      </geometry>
      <material name="yellow"/>
    </visual>
    <collision>
      <origin rpy="0 0 0" xyz="0 0 0"/>
      <geometry>
        <mesh filename="package://cute_model/meshes/cute_300es/part5.STL"/>
      </geometry>
    </collision>
  </link>
  <joint name="joint5" type="revolute">
    <origin rpy="0 0 1.57079632679" xyz="0.00145 0 0.06663"/>
    <parent link="part4"/>
    <child link="part5"/>
    <axis xyz="0 -1 0"/>
    <limit effort="120" lower="-1.8" upper="1.8" velocity="4.0"/>
  </joint>
  <link name="part6">
    <inertial>
      <origin rpy="0 0 0" xyz="-0.0060236 0.014097 -0.1881"/>
      <mass value="9.0546"/>
      <inertia ixx="0.23194" ixy="0.0017997" ixz="-0.0073867" iyy="0.23679" iyz="-0.010458" izz="0.059867"/>
    </inertial>
    <visual>
      <origin rpy="0 0 0" xyz="0 0 0"/>
      <geometry>
        <mesh filename="package://cute_model/meshes/cute_300es/part6.STL"/>
      </geometry>
      <material name="gray"/>
    </visual>
    <collision>
      <origin rpy="0 0 0" xyz="0 0 0"/>
      <geometry>
        <mesh filename="package://cute_model/meshes/cute_300es/part6.STL"/>
      </geometry>
    </collision>
  </link>
  <joint name="joint6" type="revolute">
    <origin rpy="0 0 -1.8142" xyz="0.00145 0 0.06663"/>
    <parent link="part5"/>
    <child link="part6"/>
    <axis xyz="-0.24105 0.97051 0"/>
    <limit effort="120" lower="-1.8" upper="1.8" velocity="4.0"/>
  </joint>
  <link name="part7">
    <inertial>
      <origin rpy="0 0 0" xyz="-0.015257 -0.0014931 -0.2151"/>
      <mass value="9.0546"/>
      <inertia ixx="0.23739" ixy="-7.8505E-05" ixz="0.0077441" iyy="0.23135" iyz="-0.010196" izz="0.059867"/>
    </inertial>
    <visual>
      <origin rpy="0 0 0" xyz="0 0 0"/>
      <geometry>
        <mesh filename="package://cute_model/meshes/cute_300es/part7.STL"/>
      </geometry>
      <material name="gray"/>
    </visual>
    <collision>
      <origin rpy="0 0 0" xyz="0 0 0"/>
      <geometry>
        <mesh filename="package://cute_model/meshes/cute_300es/part7.STL"/>
      </geometry>
    </collision>
  </link>
  <joint name="joint7" type="revolute">
    <origin rpy="0 0 -1.2645" xyz="0 0 0.027"/>
    <parent link="part6"/>
    <child link="part7"/>
    <axis xyz="0 0 1"/>
    <limit effort="120" lower="-2.5" upper="2.5" velocity="4.0"/>
  </joint>
  <link name="claw1">
    <inertial>
      <origin rpy="0 0 0" xyz="-0.0083363 -0.010453 0"/>
      <mass value="0.0089253"/>
      <inertia ixx="2.2065E-06" ixy="4.2939E-07" ixz="-6.4162E-22" iyy="1.3936E-06" iyz="-2.39E-21" izz="1.5605E-06"/>
    </inertial>
    <visual>
      <origin rpy="0 0 0" xyz="0 0 0"/>
      <geometry>
        <mesh filename="package://cute_model/meshes/cute_300es/claw1.STL"/>
      </geometry>
      <material name="">
        <color rgba="0.55294 0.75294 0.55294 1"/>
      </material>
    </visual>
    <collision>
      <origin rpy="0 0 0" xyz="0 0 0"/>
      <geometry>
        <mesh filename="package://cute_model/meshes/cute_300es/claw1.STL"/>
      </geometry>
    </collision>
  </link>
  <joint name="claw" type="prismatic">
    <origin rpy="1.57079632679 0 -1.6336" xyz="0.00075017 0.011926 0.1118"/>
    <parent link="part7"/>
    <child link="claw1"/>
    <axis xyz="1 0 0"/>
    <limit effort="30" lower="-0.01" upper="0.01" velocity="0.005"/>
  </joint>
  <link name="claw2">
    <inertial>
      <origin rpy="0 0 0" xyz="-0.0083363 -0.010453 1.3878E-17"/>
      <mass value="0.0089253"/>
      <inertia ixx="2.2065E-06" ixy="4.2939E-07" ixz="-1.4504E-21" iyy="1.3936E-06" iyz="-2.2066E-21" izz="1.5605E-06"/>
    </inertial>
    <visual>
      <origin rpy="0 0 0" xyz="0 0 0"/>
      <geometry>
        <mesh filename="package://cute_model/meshes/cute_300es/claw2.STL"/>
      </geometry>
      <material name="">
        <color rgba="0.55294 0.75294 0.55294 1"/>
      </material>
    </visual>
    <collision>
      <origin rpy="0 0 0" xyz="0 0 0"/>
      <geometry>
        <mesh filename="package://cute_model/meshes/cute_300es/claw2.STL"/>
      </geometry>
    </collision>
  </link>
  <joint name="claw_pris2" type="prismatic">
    <origin rpy="1.57079632679 0 1.508" xyz="-0.00075017 -0.011926 0.1118"/>
    <parent link="part7"/>
    <child link="claw2"/>
    <axis xyz="1 0 0"/>
    <limit effort="30" lower="-0.01" upper="0.01" velocity="0.005"/>
    <mimic joint="claw" multiplier="1" offset="0"/>
  </joint>
  <link name="end_link"/>
  <joint name="end_joint" type="fixed">
    <origin rpy="0 0 0" xyz="0 0 0.1118"/>
    <parent link="part7"/>
    <child link="end_link"/>
  </joint>
  <material name="aluminum">
    <color rgba="0.5 0.5 0.5 1"/>
  </material>
  <material name="plastic">
    <color rgba="0.1 0.1 0.1 1"/>
  </material>
</robot>

